Workbook

Sheet ENSO_months_piControl
A1: member | B1: month | C1: Extreme El Nino weight | D1: CP El Nino weight | E1: Neutral weight | F1: CP La Nina weight | G1: Basin-wide La Nina weight | H1: nino34_raw | I1: nino34 running mean
A2: piControl | B2: 36892 | C2: 3.1610248e-06 | D2: 1.2044125e-10 | E2: 0.0089618456 | F2: 0.067362037 | G2: 0.92367296 | H2: -2.0275788 | I2: -2.0030968 | J2: Jan | K2: Jan
A3: piControl | B3: 36923 | C3: 5.6911638e-06 | D3: 3.9402836e-11 | E3: 0.0064815864 | F3: 0.013062828 | G3: 0.98044989 | H3: -1.9786149 | I3: -1.9492332
A4: piControl | B4: 36951 | C4: 5.6443531e-06 | D4: 1.6778479e-10 | E4: 0.010183726 | F4: 0.035390164 | G4: 0.95442047 | H4: -1.841506 | I4: -1.8160001
A5: piControl | B5: 36982 | C5: 7.2078156e-06 | D5: 1.3675114e-08 | E5: 0.011131852 | F5: 0.54073114 | G5: 0.44812979 | H5: -1.6278793 | I5: -1.6679932
A6: piControl | B6: 37012 | C6: 1.5572264e-05 | D6: 4.2691192e-09 | E6: 0.001573757 | F6: 0.61995951 | G6: 0.37845116 | H6: -1.5345943 | I6: -1.5060481
A7: piControl | B7: 37043 | C7: 1.3575587e-05 | D7: 5.1896185e-09 | E7: 0.00014489463 | F7: 0.85293781 | G7: 0.14690371 | H7: -1.3556706 | I7: -1.3449335
A8: piControl | B8: 37073 | C8: 8.9356212e-07 | D8: 9.7760859e-08 | E8: 9.2177917e-05 | F8: 0.98796108 | G8: 0.011945755 | H8: -1.1445356 | I8: -1.1225307
A9: piControl | B9: 37104 | C9: 3.4720365e-07 | D9: 7.7392776e-07 | E9: 0.00014902088 | F9: 0.99624719 | G9: 0.0036026722 | H9: -0.86738596 | I9: -0.85646777
A10: piControl | B10: 37135 | C10: 1.4209436e-08 | D10: 4.2346529e-06 | E10: 1.9616618e-05 | F10: 0.99962149 | G10: 0.00035464297 | H10: -0.55748173 | I10: -0.66958261
A11: piControl | B11: 37165 | C11: 3.2474992e-09 | D11: 3.6315604e-05 | E11: 7.1194486e-05 | F11: 0.999793 | G11: 9.9489753e-05 | H11: -0.58388015 | I11: -0.6084869
A12: piControl | B12: 37196 | C12: 4.1345952e-10 | D12: 0.00038538885 | E12: 0.00015394851 | F12: 0.99943664 | G12: 2.4019484e-05 | H12: -0.68409882 | I12: -0.68102907
A13: piControl | B13: 37226 | C13: 4.2352706e-10 | D13: 0.00046996293 | E13: 0.00018432392 | F13: 0.9993235 | G13: 2.221541e-05 | H13: -0.77510824 | I13: -0.78530711
A14: piControl | B14: 37257 | C14: 3.0159025e-10 | D14: 0.00097759312 | E14: 0.00042434394 | F14: 0.99857334 | G14: 2.4722436e-05 | H14: -0.89671426 | I14: -0.79711036 | J14: Jan | K14: Jan
A15: piControl | B15: 37288 | C15: 4.8490062e-10 | D15: 0.00070119397 | E15: 0.00030330397 | F15: 0.99897479 | G15: 2.0709382e-05 | H15: -0.71950858 | I15: -0.77682053
A16: piControl | B16: 37316 | C16: 3.0464752e-09 | D16: 0.0087925673 | E16: 0.0047866437 | F16: 0.98640837 | G16: 1.2416105e-05 | H16: -0.71423876 | I16: -0.72418521
A17: piControl | B17: 37347 | C17: 3.2323541e-10 | D17: 0.033474994 | E17: 0.0029490381 | F17: 0.96357254 | G17: 3.4283702e-06 | H17: -0.73880828 | I17: -0.67603918
A18: piControl | B18: 37377 | C18: 2.7584943e-10 | D18: 0.071224551 | E18: 0.0033404416 | F18: 0.9254341 | G18: 9.0724664e-07 | H18: -0.57507051 | I18: -0.61287823
A19: piControl | B19: 37408 | C19: 1.2461482e-09 | D19: 0.058428909 | E19: 0.0052255854 | F19: 0.9363447 | G19: 8.0351953e-07 | H19: -0.52475589 | I19: -0.55643165
A20: piControl | B20: 37438 | C20: 5.4283877e-09 | D20: 0.020489872 | E20: 0.0040347983 | F20: 0.97547325 | G20: 2.0782363e-06 | H20: -0.56946856 | I20: -0.54442765
A21: piControl | B21: 37469 | C21: 1.9102035e-08 | D21: 0.01815517 | E21: 0.0068514359 | F21: 0.97498919 | G21: 4.18673e-06 | H21: -0.5390585 | I21: -0.50323656
A22: piControl | B22: 37500 | C22: 6.2767811e-08 | D22: 0.052988118 | E22: 0.020778644 | F22: 0.92623039 | G22: 2.7853728e-06 | H22: -0.40118262 | I22: -0.45326663
A23: piControl | B23: 37530 | C23: 9.5119928e-08 | D23: 0.06118931 | E23: 0.028202733 | F23: 0.91060458 | G23: 3.2818387e-06 | H23: -0.41955878 | I23: -0.43479397
A24: piControl | B24: 37561 | C24: 1.0209213e-07 | D24: 0.021843224 | E24: 0.01891614 | F24: 0.95922982 | G24: 1.0712699e-05 | H24: -0.48364052 | I24: -0.42981548
A25: piControl | B25: 37591 | C25: 9.8938695e-08 | D25: 0.016336346 | E25: 0.012389438 | F25: 0.97126344 | G25: 1.0673483e-05 | H25: -0.38624713 | I25: -0.44372135
A26: piControl | B26: 37622 | C26: 3.4583908e-08 | D26: 0.029044597 | E26: 0.011530608 | F26: 0.95942109 | G26: 3.6746287e-06 | H26: -0.46127642 | I26: -0.39284659
... A28: piControl | B28: 37681 | C28: 8.188706e-08 | D28: 0.0038946904 | E28: 0.0059984353 | F28: 0.9900762 | G28: 3.0594415e-05 | H28: -0.42639292 | I28: -0.52168934
A29: piControl | B29: 37712 | C29: 2.014546e-07 | D29: 0.0030049293 | E29: 0.028191052 | F29: 0.96861326 | G29: 0.00019056042 | H29: -0.80765889 | I29: -0.612652 | J29: Apr
A30: piControl | B30: 37742 | C30: 1.3037136e-06 | D30: 0.0024367832 | E30: 0.024343146 | F30: 0.97290974 | G30: 0.00030902492 | H30: -0.60390419 | I30: -0.64156845 | K30: May
A31: piControl | B31: 37773 | C31: 3.1437079e-07 | D31: 0.0018996864 | E31: 0.0030365375 | F31: 0.99499459 | G31: 6.8868043e-05 | H31: -0.51314227 | I31: -0.59571498
A32: piControl | B32: 37803 | C32: 2.668756e-07 | D32: 0.00049762946 | E32: 0.0014289278 | F32: 0.99793383 | G32: 0.00013934145 | H32: -0.67009848 | I32: -0.61708707
A33: piControl | B33: 37834 | C33: 2.794525e-07 | D33: 0.0011697 | E33: 0.0064173301 | F33: 0.99226988 | G33: 0.0001428142 | H33: -0.66802045 | I33: -0.67448135
A34: piControl | B34: 37865 | C34: 1.4680985e-07 | D34: 0.0012537914 | E34: 0.0089660333 | F34: 0.98963737 | G34: 0.00014266331 | H34: -0.68532511 | I34: -0.64544446
A35: piControl | B35: 37895 | C35: 9.2319653e-08 | D35: 0.0028281247 | E35: 0.0089402885 | F35: 0.98817226 | G35: 5.9234083e-05 | H35: -0.58298783 | I35: -0.60904424
A36: piControl | B36: 37926 | C36: 1.0040753e-07 | D36: 0.006055748 | E36: 0.014584253 | F36: 0.97931867 | G36: 4.1231625e-05 | H36: -0.55881978 | I36: -0.58765581
A37: piControl | B37: 37956 | C37: 3.7486286e-08 | D37: 0.00050368351 | E37: 0.0016085797 | F37: 0.99781172 | G37: 7.5980934e-05 | H37: -0.62115981 | I37: -0.6910673
A38: piControl | B38: 37987 | C38: 3.3369269e-08 | D38: 0.00015150569 | E38: 0.0014846455 | F38: 0.99817538 | G38: 0.00018843561 | H38: -0.89322232 | I38: -0.9153482
A39: piControl | B39: 38018 | C39: 1.0681718e-07 | D39: 0.00017573656 | E39: 0.010417166 | F39: 0.98852213 | G39: 0.00088486014 | H39: -1.2316625 | I39: -1.1369561
A40: piControl | B40: 38047 | C40: 1.8897404e-08 | D40: 1.1332727e-05 | E40: 0.0012745175 | F40: 0.99758067 | G40: 0.0011334631 | H40: -1.2859834 | I40: -1.284654
A41: piControl | B41: 38078 | C41: 4.6518407e-08 | D41: 2.3632288e-06 | E41: 0.0017847712 | F41: 0.99411478 | G41: 0.0040980386 | H41: -1.3363162 | I41: -1.3376846
...

Sheet ENSO_months_6ka
A1: member | B1: month | C1: Extreme El Nino weight | D1: CP El Nino weight | E1: Neutral weight | F1: CP La Nina weight | G1: Basin-wide La Nina weight | H1: nino34_raw | I1: nino34 running mean
A2: 6ka | B2: 36892 | C2: 0.00057325311 | D2: 0.00023375491 | E2: 0.0031933537 | F2: 0.93544177 | G2: 0.060557863 | H2: -0.83050908 | I2: -0.8186527 | J2: Jan | K2: Jan
A3: 6ka | B3: 36923 | C3: 0.00044907909 | D3: 0.00020245285 | E3: 0.0065888652 | F3: 0.94139402 | G3: 0.051365587 | H3: -0.80679631 | I3: -0.81266585
A4: 6ka | B4: 36951 | C4: 0.00016242663 | D4: 0.00050066145 | E4: 0.014761811 | F4: 0.96533245 | G4: 0.019242647 | H4: -0.80069216 | I4: -0.77936094
A5: 6ka | B5: 36982 | C5: 0.00025644654 | D5: 0.0013326826 | E5: 0.01300688 | F5: 0.97195904 | G5: 0.013444953 | H5: -0.73059436 | I5: -0.65536473
A6: 6ka | B6: 37012 | C6: 0.00034617053 | D6: 0.0058652454 | E6: 0.0086437042 | F6: 0.97990588 | G6: 0.0052390005 | H6: -0.43480768 | I6: -0.50716664
A7: 6ka | B7: 37043 | C7: 0.00023636037 | D7: 0.0086003048 | E7: 0.012054927 | F7: 0.97699334 | G7: 0.0021150661 | H7: -0.35609789 | I7: -0.39093833
A8: 6ka | B8: 37073 | C8: 0.00025788298 | D8: 0.018223921 | E8: 0.013847582 | F8: 0.96679249 | G8: 0.00087812261 | H8: -0.38190942 | I8: -0.40505249
A9: 6ka | B9: 37104 | C9: 0.00010056889 | D9: 0.019482529 | E9: 0.024143557 | F9: 0.95604464 | G9: 0.0002287026 | H9: -0.47715017 | I9: -0.46679964
A10: 6ka | B10: 37135 | C10: 8.6726842e-05 | D10: 0.013482072 | E10: 0.036157623 | F10: 0.94983657 | G10: 0.00043700369 | H10: -0.54133934 | I10: -0.4915791
A11: 6ka | B11: 37165 | C11: 0.00025238201 | D11: 0.0047388158 | E11: 0.019100496 | F11: 0.97124024 | G11: 0.0046680697 | H11: -0.45624778 | I11: -0.47680673
A12: 6ka | B12: 37196 | C12: 0.00061306507 | D12: 0.0035687947 | E12: 0.025499704 | F12: 0.95373479 | G12: 0.016583648 | H12: -0.43283306 | I12: -0.4330607
A13: 6ka | B13: 37226 | C13: 0.0045377776 | D13: 0.008880893 | E13: 0.21528362 | F13: 0.65761825 | G13: 0.11367946 | H13: -0.41010125 | I13: -0.36272081
A14: 6ka | B14: 37257 | C14: 0.01016631 | D14: 0.010027357 | E14: 0.073909446 | F14: 0.75158008 | G14: 0.1543168 | H14: -0.24522811 | I14: -0.21997839
... A22: 6ka | B22: 37500 | C22: 0.14018235 | D22: 0.82427143 | E22: 0.035488651 | F22: 4.5333838e-08 | G22: 5.7522585e-05 | H22: 1.1000818 | I22: 1.028595
A23: 6ka | B23: 37530 | C23: 0.021131806 | D23: 0.91476339 | E23: 0.064104658 | F23: 5.76231e-08 | G23: 9.142176e-08 | H23: 1.3599493 | I23: 1.2642989 | J23: Oct
A24: 6ka | B24: 37561 | C24: 0.0023770001 | D24: 0.78640349 | E24: 0.21121876 | F24: 7.5005119e-07 | G24: 5.2908923e-10 | H24: 1.3328656 | I24: 1.3209808 | K24: Nov
A25: 6ka | B25: 37591 | C25: 0.00065243203 | D25: 0.67385266 | E25: 0.32549368 | F25: 1.2342111e-06 | G25: 6.0944594e-11 | H25: 1.2701275 | I25: 1.2794945
A26: 6ka | B26: 37622 | C26: 0.00063962132 | D26: 0.68572865 | E26: 0.31358034 | F26: 5.1391737e-05 | G26: 1.013277e-10 | H26: 1.2354905 | I26: 1.1579397
A27: 6ka | B27: 37653 | C27: 0.00017971825 | D27: 0.53909505 | E27: 0.46047737 | F27: 0.00024786042 | G27: 1.2910172e-09 | H27: 0.96820114 | I27: 0.98041342
A28: 6ka | B28: 37681 | C28: 1.8323777e-05 | D28: 0.5023282 | E28: 0.49726756 | F28: 0.00038591867 | G28: 1.2686549e-11 | H28: 0.73754858 | I28: 0.77292405
A29: 6ka | B29: 37712 | C29: 8.9158643e-06 | D29: 0.49144641 | E29: 0.50812306 | F29: 0.00042161392 | G29: 1.1182521e-11 | H29: 0.61302244 | I29: 0.68249675
A30: 6ka | B30: 37742 | C30: 1.6032054e-05 | D30: 0.55806257 | E30: 0.43941097 | F30: 0.0025104284 | G30: 1.0088499e-12 | H30: 0.69691922 | I30: 0.7037282
A31: 6ka | B31: 37773 | C31: 5.1909361e-05 | D31: 0.55721647 | E31: 0.44201472 | F31: 0.00071690443 | G31: 6.581188e-12 | H31: 0.80124295 | I31: 0.79749327
A32: 6ka | B32: 37803 | C32: 0.0040153747 | D32: 0.67495361 | E32: 0.32101679 | F32: 1.3473257e-05 | G32: 7.5644081e-07 | H32: 0.89431765 | I32: 1.0327258
A33: 6ka | B33: 37834 | C33: 0.048339848 | D33: 0.90923039 | E33: 0.042428869 | F33: 8.8980877e-09 | G33: 8.8223928e-07 | H33: 1.4026169 | I33: 1.4339125
A34: 6ka | B34: 37865 | C34: 0.19268649 | D34: 0.80535265 | E34: 0.0019608355 | F34: 4.059012e-14 | G34: 2.6798207e-08 | H34: 2.004803 | I34: 1.899191
A35: 6ka | B35: 37895 | C35: 0.30157103 | D35: 0.69808346 | E35: 0.00034551515 | F35: 2.3058442e-18 | G35: 5.1517402e-11 | H35: 2.2901531 | I35: 2.2343524
A36: 6ka | B36: 37926 | C36: 0.29173513 | D36: 0.70750697 | E36: 0.00075790025 | F36: 8.9209697e-21 | G36: 7.6506966e-14 | H36: 2.408101 | I36: 2.4615709
... A38: 6ka | B38: 37987 | C38: 0.60418681 | D38: 0.39577005 | E38: 4.3141181e-05 | F38: 6.8079529e-23 | G38: 3.5271462e-14 | H38: 3.0241433 | I38: 2.9391206
A39: 6ka | B39: 38018 | C39: 0.57758534 | D39: 0.42238498 | E39: 2.9683808e-05 | F39: 2.2249561e-22 | G39: 4.2338013e-13 | H39: 3.1067598 | I39: 3.0961971 | K39: Feb
A40: 6ka | B40: 38047 | C40: 0.660693 | D40: 0.33930339 | E40: 3.604392e-06 | F40: 2.9239268e-23 | G40: 1.8038757e-11 | H40: 3.1576881 | I40: 3.0470681 | J40: Mar
A41: 6ka | B41: 38078 | C41: 0.43236251 | D41: 0.56752399 | E41: 0.00011349578 | F41: 1.3080996e-16 | G41: 3.5211195e-10 | H41: 2.8767566 | I41: 2.7988088
A42: 6ka | B42: 38108 | C42: 0.3620645 | D42: 0.63760532 | E42: 0.00033016124 | F42: 7.3519202e-17 | G42: 1.8608194e-08 | H42: 2.3619818 | I42: 2.361135
A43: 6ka | B43: 38139 | C43: 0.74367685 | D43: 0.25604173 | E43: 0.00028023554 | F43: 3.0209166e-18 | G43: 1.1781559e-06 | H43: 1.8446667 | I43: 2.0144809
A44: 6ka | B44: 38169 | C44: 0.69456639 | D44: 0.30004262 | E44: 0.0053730984 | F44: 6.1690345e-16 | G44: 1.789406e-05 | H44: 1.8367943 | I44: 1.8831621
A45: 6ka | B45: 38200 | C45: 0.73179368 | D45: 0.26685616 | E45: 0.0013401773 | F45: 4.5385568e-16 | G45: 9.9903257e-06 | H45: 1.9680253 | I45: 1.7375594
A46: 6ka | B46: 38231 | C46: 0.92623899 | D46: 0.07065633 | E46: 0.003052009 | F46: 8.1053211e-18 | G46: 5.2675891e-05 | H46: 1.4078585 | I46: 1.4309002
A47: 6ka | B47: 38261 | C47: 0.90582852 | D47: 0.02376835 | E47: 0.067885947 | F47: 5.9742524e-17 | G47: 0.0025171851 | H47: 0.9168169 | I47: 1.0364634
A48: 6ka | B48: 38292 | C48: 0.88945827 | D48: 0.0046812436 | E48: 0.096270607 | F48: 6.9589805e-19 | G48: 0.0095898841 | H48: 0.7847148 | I48: 0.81310209
...

Sheet GMM_scan_piControl
A1: covariance_type | B1: k | C1: run | D1: bic | E1: gmm
A2: spherical | B2: 2 | C2: 0 | D2: 19850.494 | E2: GaussianMixture(covariance_type='spherical', n_components=2, random_state=42)
A3: spherical | B3: 2 | C3: 1 | D3: 19829.654 | E3: GaussianMixture(covariance_type='spherical', n_components=2, random_state=43)
A4: spherical | B4: 2 | C4: 2 | D4: 19849.758 | E4: GaussianMixture(covariance_type='spherical', n_components=2, random_state=44)
A5: spherical | B5: 2 | C5: 3 | D5: 19821.433 | E5: GaussianMixture(covariance_type='spherical', n_components=2, random_state=45)
A6: spherical | B6: 2 | C6: 4 | D6: 19850.061 | E6: GaussianMixture(covariance_type='spherical', n_components=2, random_state=46)
A7: spherical | B7: 2 | C7: 5 | D7: 19828.232 | E7: GaussianMixture(covariance_type='spherical', n_components=2, random_state=47)
A8: spherical | B8: 2 | C8: 6 | D8: 19850.061 | E8: GaussianMixture(covariance_type='spherical', n_components=2, random_state=48)
A9: spherical | B9: 2 | C9: 7 | D9: 19853.599 | E9: GaussianMixture(covariance_type='spherical', n_components=2, random_state=49)
A10: spherical | B10: 2 | C10: 8 | D10: 19829.654 | E10: GaussianMixture(covariance_type='spherical', n_components=2, random_state=50)
A11: spherical | B11: 2 | C11: 9 | D11: 19849.576 | E11: GaussianMixture(covariance_type='spherical', n_components=2, random_state=51)
A12: spherical | B12: 2 | C12: 10 | D12: 19850.48 | E12: GaussianMixture(covariance_type='spherical', n_components=2, random_state=52)
A13: spherical | B13: 2 | C13: 11 | D13: 19853.599 | E13: GaussianMixture(covariance_type='spherical', n_components=2, random_state=53)
... A7001: full | B7001: 8 | C7001: 249 | D7001: 17816.053 | E7001: GaussianMixture(n_components=8, random_state=291)

Sheet Best_GMM_piControl
A1: random_state | B1: best_k | C1: best_bic_x | D1: best_bic_y | E1: gmm
A2: 42 | B2: 5 | C2: 17778.349 | D2: 17778.349 | E2: GaussianMixture(n_components=5, random_state=42)
A3: 43 | B3: 5 | C3: 17777.388 | D3: 17777.388 | E3: GaussianMixture(n_components=5, random_state=43)
A4: 44 | B4: 5 | C4: 17778.762 | D4: 17778.762 | E4: GaussianMixture(n_components=5, random_state=44)
A5: 45 | B5: 5 | C5: 17778.349 | D5: 17778.349 | E5: GaussianMixture(n_components=5, random_state=45)
A6: 46 | B6: 5 | C6: 17778.774 | D6: 17778.774 | E6: GaussianMixture(n_components=5, random_state=46)
A7: 47 | B7: 5 | C7: 17778.762 | D7: 17778.762 | E7: GaussianMixture(n_components=5, random_state=47)
A8: 48 | B8: 7 | C8: 17776.273 | D8: 17776.273 | E8: GaussianMixture(n_components=7, random_state=48)
A9: 49 | B9: 5 | C9: 17778.91 | D9: 17778.91 | E9: GaussianMixture(n_components=5, random_state=49)
A10: 50 | B10: 5 | C10: 17778.762 | D10: 17778.762 | E10: GaussianMixture(n_components=5, random_state=50)
A11: 51 | B11: 5 | C11: 17778.762 | D11: 17778.762 | E11: GaussianMixture(n_components=5, random_state=51)
A12: 52 | B12: 7 | C12: 17774.523 | D12: 17774.523 | E12: GaussianMixture(n_components=7, random_state=52)
A13: 53 | B13: 7 | C13: 17774.837 | D13: 17774.837 | E13: GaussianMixture(n_components=7, random_state=53)
... A251: 291 | B251: 5 | C251: 17777.357 | D251: 17777.357 | E251: GaussianMixture(n_components=5, random_state=291)

Sheet K_counts_piControl
A1: k | B1: count
A2: 5 | B2: 185
A3: 6 | B3: 2
A4: 7 | B4: 63

Sheet Sheet1
B2: period | C2: Extreme El Nino | D2: CP El Nino | E2: Neutral | F2: CP La Nina | G2: Basin-wide La Nina
B3: piControl | C3: =VALUE(ENSO_months_piControl!C2404) -> 12 | D3: =VALUE(ENSO_months_piControl!D2404) -> 33 | E3: =VALUE(ENSO_months_piControl!E2404) -> 17 | F3: =VALUE(ENSO_months_piControl!F2404) -> 15 | G3: =VALUE(ENSO_months_piControl!G2404) -> 16
B4: 6ka | C4: =VALUE(ENSO_months_6ka!C2404) -> 1 | D4: =VALUE(ENSO_months_6ka!D2404) -> 35 | E4: =VALUE(ENSO_months_6ka!E2404) -> 24 | F4: =VALUE(ENSO_months_6ka!F2404) -> 35 | G4: =VALUE(ENSO_months_6ka!G2404) -> 2
A6: Column1 | B6: raw | C6: raw2 | D6: running | E6: running2
B7: piControl | C7: 6ka | D7: piControl | E7: 6ka
A8: Jan | B8: 28 | C8: 17 | D8: 33 | E8: 18
A9: Feb | B9: 13 | C9: 7 | D9: 9 | E9: 7
A10: Mar | B10: 4 | C10: 4 | D10: 4 | E10: 4
A11: Apr | B11: 5 | C11: 3 | D11: 5 | E11: 1
A12: May | B12: 3 | C12: 0 | D12: 3 | E12: 1
A13: Jun | B13: 0 | C13: 0 | D13: 1 | E13: 0
A14: Jul | B14: 1 | C14: 1 | D14: 0 | E14: 2
A15: Aug | B15: 1 | C15: 6 | D15: 1 | E15: 3
A16: Sep | B16: 3 | C16: 12 | D16: 0 | E16: 15
A17: Oct | B17: 10 | C17: 18 | D17: 9 | E17: 11
A18: Nov | B18: 10 | C18: 6 | D18: 13 | E18: 12
A19: Dec | B19: 17 | C19: 15 | D19: 17 | E19: 15
A20: sum | B20: =SUM(B8:B19) -> 95 | C20: =SUM(C8:C19) -> 89 | D20: =SUM(D8:D19) -> 95 | E20: =SUM(E8:E19) -> 89
